Workbook

Sheet 🏠 Home
A1: 🚀 Risk Up Front — Project Mega Workbook
A2: Four principles. Four documents. Two meetings. — A complete, living toolkit for running a project the RUF way, built for humans AND AI agents.
A4: 👋 Welcome
A5: This workbook is the single source of truth for a project run with the Risk Up Front (RUF) approach (Josephs & Rubenstein, 'Risk Up Front: Managing Projects in a Complex World', 2018).
A6: It does three jobs at once:
A7: 1️⃣ TEMPLATES — every RUF artifact, ready to fill in: Project Statement, Team List, Individual Accountabilities, Risk Action Plan, Weekly Schedule, WAM log, plus the supporting logs and the Cost of Being Late.
A8: 2️⃣ TEACHER — the 📖 RUF 101 sheet and per-sheet help boxes teach the framework as you use it. A new team member (or a brand-new AI agent) can become fluent in RUF from this file alone.
A9: 3️⃣ AI-NATIVE — the 🤖 sheets give any AI agent full framework context, this workbook's exact schema, and step-by-step prompt instructions for ingesting meeting transcripts and emails into the right sheets.
A11: 🧭 The RUF system at a glance
B12: 4 PRINCIPLES (the culture) | C12: 4 DOCUMENTS (the paper) | D12: 2 MEETINGS (the rhythm) | E12: 4 LEVERS (how culture changes)
B13: Accountability — 'Singular ownership of a result' | C13: 📜 Project Statement | D13: Definition Meeting (DKDK) | E13: Language
B14: Transparency — 'Team-wide clarity of what is so' | C14: 👥 Team List + 🧭 Individual Accountabilities | D14: 🤝 Weekly Accountability Meeting | E14: Structures
B15: Integrity — 'Do what you say' | C15: 📅 Weekly Schedule | E15: Practices
B16: Commitment — 'It will be so, even in the face of circumstances' | C16: ⚠️ Risk Action Plan (RAP) | E16: Metrics
A18: 🗺 Map of this workbook
B19: Sheet | C19: What it is | D19: Who uses it | E19: When
B20: 📖 RUF 101 | C20: The framework explained: principles, levers, CEI risk form, meetings, timeline, glossary | D20: Everyone — read first | E20: Once, then as reference
B21: 📜 Project Statement | C21: The 1–3 page charter around the 5W tradeoff; the object of team commitment | D21: Project Leader + team | E21: Definition; reviewed weekly
B22: 👥 Team List | C22: Names (never titles alone), accountabilities, allocation, explicit agreement | D22: Project Leader | E22: Definition; kept current
B23: 🧭 Individual Accountab. | C23: One block per person: the results they singularly own | D23: Every team member | E23: Definition
B24: ⚠️ Risk Action Plan | C24: Risks in Cause–Effect–Impact form, owners, mitigation actions | D24: Whole team | E24: Continuously; walked at every WAM
B25: ✅ Actions | C25: Every owned, dated task (mitigations, cleanups, follow-ups) | D25: Owners | E25: Continuously
B26: 📅 Weekly Schedule | C26: The project as weekly deliverables, one owner each, done/not-done | D26: Whole team | E26: Weekly
B27: 🤝 WAM Agenda & Log | C27: Standing agenda + one log row per weekly meeting | D27: Project Leader (chair) | E27: Every week
B28: 🚧 Issues Log | C28: Known present problems (risks that happened live here) | D28: Owners | E28: As they arise
B29: 🧮 Decision Log | C29: Decisions written down = transparency | D29: Everyone | E29: As decided
B30: 💸 Cost of Being Late | C30: Linear + nonlinear lateness costs and the agreed narrative | D30: Team + stakeholders | E30: Definition; on change
... B37: 🤖 AI · Email Ingestion | C37: Prompt instructions: email threads → commitments, risks, decisions, issues | D37: AI agents | E37: On email batches
A39: 🎨 Color legend
B40: Emerald | C40: Accountability / Team sheets
B41: Azure | C41: Transparency / Schedule
B42: Bronze | C42: Integrity / Costs & logs
B43: Plum | C43: Commitment / WAM
B44: Crimson | C44: Risk Action Plan
B45: Violet | C45: AI-agent sheets
A47: ⚡ Quick start (a PM's first hour)
A48: 1. Read 📖 RUF 101 (10 min). 2. Draft the 📜 Project Statement — especially WHY NOT. 3. Put names on 👥 Team List.
A49: 4. Run a risk-surfacing session and load the ⚠️ RAP in CEI form. 5. Fill 💸 Cost of Being Late with the team.
A50: 6. Hold the Definition Meeting (line-by-line read of the Statement). 7. Retire the biggest novel risks.
A51: 8. Team Commitment decision point → dates flip from Target to Committed. 9. Run 🤝 WAMs weekly; score the 📅 Weekly Schedule; watch the 📊 Dashboard.
...

Sheet 📖 RUF 101
A1: 📖 RUF 101 — The Framework in One Sheet
A2: Everything a human needs to run this workbook the Risk Up Front way. (AI agents: your denser version is 🤖 AI · Framework Context.)
A4: 💡 The big idea
A5: Projects live on a cost-of-change curve: changes are cheap early and brutally expensive late. 'It's like gravity: it's there whether you believe in it or not.'
A6: Left alone, teams do the opposite of what the curve demands — 'optimistic procrastination': assume all will go smoothly and defer risk work until later. Urgency then arrives exactly when changes cost the most (the death march).
A7: RUF's one move: SHIFT URGENCY TO THE FRONT. Force risks, disagreements and hidden assumptions into the open during Definition, when they are cheap to fix. The whole method — four principles, four documents, two meetings — is machinery for that one move.
A8: The most dangerous risks live in the team's BLIND SPOT (what it doesn't know it doesn't know). 'The fact that an individual knows something is different than a team knowing something.' RUF's documents and meetings exist to drain the blind spot systematically.
A10: 🏛 The four principles (canonical definitions)
B11: Principle | C11: Canonical definition | D11: What it looks like in practice | E11: Anti-pattern it kills
B12: Accountability | C12: 'Singular ownership of a result.' | D12: Every deliverable, risk and action has exactly ONE name — a person, never a title or department. Owners AGREE to accountabilities (not assigned unilaterally) and are on the hook to CAUSE the result, finding resources if needed. | E12: Shared ownership; 'the team owns it'; project democracy (consensus inside an owner's area).
B13: Transparency | C13: 'Team-wide clarity of what is so.' | D13: Decisions written down in actively reviewed documents; line-by-line team review; measurable success criteria everyone confirms they truly agree on; over-communication as default. | E13: Private knowledge, hallway decisions, status theater.
B14: Integrity | C14: 'Do what you say.' | D14: Depersonalized: 'Was a commitment made, and was it kept?' When a commitment is at risk, the owner cleans it up EARLY — before the date. Publicly accounting for results improves results. | E14: Silent slips; discovering misses after the deadline.
B15: Commitment | C15: 'It will be so, even in the face of circumstances.' | D15: Language of commitment ('I will deliver X by Y') replaces language of hope ('I'll try'). Before accepting: Do we agree what done means? What might prevent it? The right to say no is what makes yes meaningful. | E15: Weasel words; imposed dates; 'yes' without room for 'no'.
A17: 🎚 The four levers — how you actually change culture
A18: Principles are engineered into a team via four levers (distinct from the principles — a common confusion):
A19: • LANGUAGE — driving values through conversation (commitment language, CEI risk form, 'accountable owner').
A20: • STRUCTURES — how you spend money and deploy resources (cross-functional team from day one, singular ownership).
A21: • PRACTICES — reliably repeated or triggered activities (line-by-line review, Definition Meeting, WAM).
A22: • METRICS — the results you choose to measure ('the simple act of transparently accounting for results improves results'): weekly completion rate, risks retired, commitments kept.
A24: ⚠️ The language of risk — CEI form
A25: Every risk is stated as: 'Because of [CAUSE — a fact, verifiably true today], [EFFECT — an uncertain future event] may occur, resulting in [IMPACT — consequence to the project].'
A26: CAUSE must be a present fact (kills vague anxiety, forces evidence). EFFECT is uncertain and future (if it already happened it's an ISSUE, not a risk). IMPACT ties it to schedule/cost/scope/quality — which is what justifies spending on mitigation.
A27: Prioritize by exposure AND by NOVELTY: a risk this team has retired ten times is routine regardless of impact; a risk nobody here has retired before deserves the scarce early urgency.
A28: The standing weekly question: 'What is the most likely reason this project will fail?' — the answer always goes on the RAP with an owner.
A30: 🤝 The two meetings — and the DKDK taxonomy
... A42: 📚 Mini-glossary
B43: Term | C43: Meaning
B44: Blind Spot | C44: What the team doesn't know it doesn't know — the source of the worst risks.
B45: CEI | C45: Cause–Effect–Impact: the mandatory linguistic form of a risk.
B46: Cleanup | C46: Proactively flagging + renegotiating an at-risk commitment BEFORE its date. Integrity in action.
B47: Cost of Being Late | C47: Agreed narrative + numbers (linear per-week + nonlinear step costs) of lateness. Prices urgency.
B48: Decision Point | C48: RUF's lightweight gate; Team Commitment is the pivotal one.
B49: DKDK Meeting | C49: 'Don't Know you Don't Know' — reveals blind-spot issues; never solves on the spot.
B50: Language of hope | C50: 'I'll try', 'should be fine', 'hopefully' — effort-talk that predicts nothing. Replace with commitment.
B51: Optimistic procrastination | C51: The default tendency to assume smooth sailing and defer risk work to 'later'.
B52: RAP | C52: Risk Action Plan — the CEI-form risk register with owners and dated mitigation actions.
B53: Retire (a risk) | C53: Mitigate to closure. ~25–30% of early risks retired ≈ ready to commit (rule of thumb).
B54: WAM | C54: Weekly Accountability Meeting — the weekly DKDK heartbeat.
... B56: 5W Tradeoff | C56: Why, What, When, Who, WHY NOT — the frame of the Project Statement.

Sheet 📜 Project Statement
A1: 📜 RUF Project Statement
A2: One to three pages. The object of team commitment. Read line-by-line at the Definition Meeting. Built on the 5W Tradeoff: Why · What · When · Who · Why Not.
A4: 💡 HOW TO USE: Fill every field in plain language a new team member could understand. Keep it short enough to read aloud. Every date is a TARGET until the Team Commitment decision point — then it becomes a COMMITMENT. Review this document at every WAM; any edit after commitment is a conscious, visible change decision.
A6: 🪪 Identity
A7: Project Name
A8: Project Leader
A9: One name. The singular accountable owner of the project result — never a department or a pair.
A10: Status | B10: Definition
A11: Version / Last updated | B11: v0.1 —
A13: ❓ WHY — The Opportunity
A14: 💡 Why this project, why now? What happens if we do nothing? This is the story that justifies the team's urgency.
A15: Opportunity / Problem
A16: Strategic fit
A18: 🎯 WHAT — Deliverables & Success Criteria
A19: 💡 Deliverables are nouns, verifiable as done/not-done. Success criteria must be MEASURABLE and 'necessary and sufficient' — every team member must confirm they really agree on what each item means.
A20: # | B20: Deliverable | C20: Description | D20: Measure of success (transparent, verifiable) | E20: Accountable Owner (one name) | F20: Target/Committed date
A21: 1
A22: 2
A23: 3
A24: 4
A25: 5
A26: 6
A27: 7
A28: 8
A30: 🚧 Scope Boundaries — IS / IS NOT
A31: 💡 The IS NOT column prevents the most expensive class of late change: silent scope growth. Be explicit about near-misses people might assume are in scope.
A32: ✅ This project IS… | D32: 🚫 This project IS NOT…
A40: 🗓 WHEN — Key Dates & Decision Points
A41: Milestone / Decision Point | B41: Type | C41: Date | D41: Target or Committed? | E41: Owner | F41: Notes
A42: Definition Meeting | B42: DKDK Meeting | D42: Target
A43: Team Commitment | B43: Decision Point | D43: Target | F43: Gate: ~25–30% of early-identified risks retired
A45: Release | B45: Decision Point | D45: Target
A51: 👥 WHO — Team & Skills (summary; full roster on 👥 Team List)
A52: Functions required to ship
A53: Engineering, QA, support, sales, legal, ops, manufacturing, marketing… A function needed to ship with no name on the Team List is a structural risk — add it to the RAP.
A55: ⚖️ WHY NOT — Risks, Costs & Tradeoffs (the honest case against)
A56: 💡 The distinctive fifth W. Summarize the top risks and what this project displaces. If Why Not overwhelms Why, change the definition: 'If your project has too many risks, it's time to evaluate your Project Definition.' Full risk detail lives on the ⚠️ RAP sheet.
A57: Top risks (summary)
A58: Tradeoffs / displaced work
A59: Cost of being late (summary)
...

Sheet 👥 Team List
A1: 👥 RUF Team List
A2: Names, never job titles alone. Everyone who holds an accountability on this project — the full cross-functional team.
A4: 💡 HOW TO USE: One row per person. 'Accountabilities' are RESULTS this person singularly owns (nouns, verifiable), not activities. A person is on this list only when they have AGREED to their accountabilities and allocation — accountability imposed without consent is not accountability. Each person also completes a one-pager on the 🧭 Individual Accountabilities sheet.
A6: Name | B6: Role on project | C6: Function / Dept | D6: Accountabilities (results singularly owned) | E6: % time | F6: Agreed & committed? | G6: Date agreed | H6: Contact | I6: Notes / coverage risks
B7: Project Leader | D7: The project result: delivery of the Project Statement in full
A27: 🧩 Function coverage check
A28: 💡 List every function needed to SHIP (not just build). Any function without a name above is a structural risk — add it to the ⚠️ RAP in CEI form.
A29: Function needed to ship | B29: Covered by (name) | C29: Gap? (auto-flag empty)
A30: Engineering / Build
A31: QA / Test
A32: Operations / Support
A33: Sales / Marketing
A34: Legal / Compliance
A35: Finance

Sheet 🧭 Individual Accountab.
A1: 🧭 Individual Accountabilities Documents
A2: One block per team member: the results they singularly own on this project. The written form of 'singular ownership of a result.'
A4: 💡 HOW TO USE: Duplicate the block below for each team member (copy the whole block of rows). Write accountabilities as RESULTS ('Signed-off test plan', 'Production deployment live'), never activities ('help with testing'). The owner drafts their own block, then the team reviews it line-by-line — gaps and overlaps between blocks are risks: send them to the RAP.
A6: 🧑 Team member 1
A7: Name
A8: Role on project
A9: Accountability # | B9: Result I singularly own (noun, verifiable) | C9: What 'done' means (agreed with team) | D9: Key dependencies / who I need | E9: Due (week of) | F9: Status / notes
A10: 1
A11: 2
A12: 3
A13: 4
A14: I agree to own these results
A15: Signature/initials + date. This is an agreement, not an assignment.
A17: 🧑 Team member 2
A18: Name
A19: Role on project
A20: Accountability # | B20: Result I singularly own (noun, verifiable) | C20: What 'done' means (agreed with team) | D20: Key dependencies / who I need | E20: Due (week of) | F20: Status / notes
A21: 1
A22: 2
A23: 3
A24: 4
A25: I agree to own these results
A26: Signature/initials + date. This is an agreement, not an assignment.
A28: 🧑 Team member 3
A29: Name
A30: Role on project
A31: Accountability # | B31: Result I singularly own (noun, verifiable) | C31: What 'done' means (agreed with team) | D31: Key dependencies / who I need | E31: Due (week of) | F31: Status / notes
A32: 1
A33: 2
A34: 3
A35: 4
A36: I agree to own these results
A37: Signature/initials + date. This is an agreement, not an assignment.
A39: 🧑 Team member 4
A40: Name
A41: Role on project
A42: Accountability # | B42: Result I singularly own (noun, verifiable) | C42: What 'done' means (agreed with team) | D42: Key dependencies / who I need | E42: Due (week of) | F42: Status / notes
A43: 1
A44: 2
A45: 3
...

Sheet ⚠️ Risk Action Plan
A1: ⚠️ Risk Action Plan (RAP)
A2: Every risk in Cause–Effect–Impact form, with one owner and dated mitigation actions. Reviewed at every WAM. A conversation tool, not a compliance archive.
A4: 💡 HOW TO WRITE A RISK (CEI form): 'Because of [CAUSE — a fact, verifiably true today], [EFFECT — an uncertain future event] may occur, resulting in [IMPACT — consequence to schedule/cost/scope/quality].' If the effect has ALREADY happened it is not a risk — move it to the 🚧 Issues Log. Prioritize by exposure AND by NOVELTY: risks the team has never retired before deserve the most early urgency. Success in Definition looks like this list growing fast — a fat RAP means the blind spot is draining. Gate rule of thumb: don't commit the schedule until ~25–30% of early-identified risks are Retired.
A6: Risk ID | B6: CAUSE — Because of… (a fact, true today) | C6: EFFECT — …may occur (uncertain future event) | D6: IMPACT — …resulting in (consequence to the project) | E6: Prob. | F6: Impact | G6: Novelty to team | H6: Priority | I6: Accountable Owner (one name) | J6: Mitigation actions (each becomes a row on ✅ Actions) | K6: Next action due | L6: Status | M6: Date identified | N6: Notes / WAM discussion
A7: R-001 | B7: The vendor's API documentation is incomplete and their support SLA is 10 business days | C7: Integration defects may be discovered late in system test | D7: 2–4 week slip to the committed release date and rework across two teams | E7: M | F7: H | G7: Novel | H7: P1 | J7: 1) Build API test harness by wk 3 (owner: ___) 2) Escalation contact secured at vendor (owner: ___) | L7: Open | N7: EXAMPLE ROW — replace with your own. Note the cause is a verifiable fact.
A39: 🎤 The standing question — ask it every week
A40: 💡 “What is the most likely reason this project will fail?” Ask it at every WAM. Whatever the answer is, it belongs on this sheet in CEI form with an owner.

Sheet ✅ Actions
A1: ✅ Action Tracker
A2: Every owned, dated task — risk mitigations, WAM cleanups, decision follow-ups. One owner per action. Always.
A4: 💡 HOW TO USE: Actions are the unit of motion in RUF. Each mitigation listed on the ⚠️ RAP gets its own row here (Source = risk ID). An action has ONE owner (a name that agreed), a committed date, and a binary done/not-done outcome. If an action's date is at risk, the owner cleans it up BEFORE the date — that's integrity.
A6: Action ID | B6: Action (verb — concrete and verifiable) | C6: Source (Risk/Issue/Decision/WAM ID) | D6: Accountable Owner | E6: Committed date | F6: Status | G6: Done date | H6: Kept commitment? | I6: Cleanup notes (if renegotiated) | J6: Week (for WAM)

Sheet 📅 Weekly Schedule
A1: 📅 RUF Weekly Schedule
A2: The whole project as weekly deliverables, each owned by one named person. Done or not done — no percentages.
A4: 💡 HOW TO USE: Rows are DELIVERABLES (nouns, verifiable), not activities — 'Draft test plan reviewed by QA' not 'work on testing'. Each has ONE owner and a committed week. At the WAM each row for the closing week is scored Done / Not done — that feeds the Weekly Completion Rate on the 📊 Dashboard, RUF's signature health metric. Slips are renegotiated visibly (cleanup), never silently moved.
A6: Week # | B6: Week of (Mon) | C6: Deliverable (noun — verifiable done/not-done) | D6: Accountable Owner | E6: What 'done' means | F6: Committed? | G6: Scored at WAM | H6: If not done: cleanup | I6: Notes | J6: Carry-over of

Sheet 🤝 WAM Agenda & Log
A1: 🤝 Weekly Accountability Meeting (WAM)
A2: The weekly heartbeat. A DKDK meeting: it exists to REVEAL, not to solve. Start on time. End on time.
A4: 📋 Standing agenda (timebox ~30–45 min)
A5: Step | B5: What happens
A6: 1. Start on time | B6: Integrity begins with the meeting itself. Note who is present.
A7: 2. Score last week's commitments | B7: Walk the 📅 Weekly Schedule rows for the closing week. Each is publicly Done / Not done. Compute the completion rate. No blame — transparent accounting of results improves results.
A8: 3. Clean up broken commitments | B8: For each Not-done: acknowledge, root-cause briefly, re-commit with a new date. Cleanups are logged on ✅ Actions.
A9: 4. Walk the Risk Action Plan | B9: Top risks first (P1s and Novel). Check mitigation actions. Add newly surfaced risks in CEI form. Retire mitigated ones.
A10: 5. Ask the standing question | B10: “What is the most likely reason this project will fail?” The answer goes on the RAP with an owner.
A11: 6. Make next week's commitments | B11: Each owner states, in the language of commitment: 'I will deliver X by Y.' Two checks: Do we agree what done means? What might prevent it?
A12: 7. End on time | B12: Issues raised get owners and go to issue meetings. The WAM reveals; it does not solve.
A14: 🗒 WAM Log — one row per meeting
A15: 💡 Fill this every week. AI agents ingesting meeting transcripts append here (see 🤖 AI · Transcript Ingestion). Completion rate = Done ÷ (Done + Not done) from the 📅 Weekly Schedule for that week.
A16: Date | B16: Attendees (absent flagged) | C16: Answer to 'most likely reason to fail' | D16: New risks added (IDs) | E16: Completion rate % | F16: Started on time? | G16: Cleanups made (action IDs) | H16: Notes / decisions referred out

Sheet 🚧 Issues Log
A1: 🚧 Issues Log
A2: Known, present problems — already true. (Uncertain future problems are RISKS: they belong on the ⚠️ RAP in CEI form.)
A4: 💡 RISK vs ISSUE: A risk MAY happen (goes to RAP). An issue HAS happened / IS true now (goes here). When a risk materializes, set its RAP status to 'Became issue' and open a row here referencing it. Issues get solved in ISSUE MEETINGS with the right small group — not in the WAM (the WAM only reveals and assigns).
A6: Issue ID | B6: Issue (what is true now) | C6: From risk (RAP ID, if any) | D6: Accountable Owner | E6: Severity | F6: Status | G6: Issue meeting date | H6: Resolution / decision | I6: Actions opened (IDs)

Sheet 🧮 Decision Log
A1: 🧮 Decision Log
A2: Write decisions down — 'the most important improvement teams make.' Transparency is team-wide clarity of what is so.
A4: 💡 HOW TO USE: Log every decision that shapes the project — scope calls, tradeoffs, decision-point outcomes. Decisions inside an owner's area of accountability are THEIRS to make (no 'project democracy'); the log makes the decision visible, not re-litigable. AI agents ingesting emails/transcripts append rows here (see the 🤖 AI sheets).
A6: Decision ID | B6: Decision (what was decided) | C6: Context / alternatives considered | D6: Decided by (accountable owner) | E6: Date | F6: Consequences (scope/schedule/cost) | G6: Communicated to | H6: Source (meeting/email/WAM ref)

Sheet 💸 Cost of Being Late
A1: 💸 Cost of Being Late
A2: Not a single number — a narrative of factors and costs. The compelling story that gives the team the incentive to hit their dates.
A4: 💡 HOW TO USE: The whole cross-functional team must consider, articulate, discuss and AGREE on this. It prices the team's urgency and creates the context for mitigation spending ('the test machines cost less than one day of lateness'). Revisit whenever scope or market timing changes.
A6: 📈 Linear costs — accumulate per week late
A7: Factor | B7: Basis / evidence | C7: Cost per week | D7: Currency | E7: Confidence | F7: Agreed by team? | G7: Narrative
A8: Lost profit / revenue
A9: Delayed cost savings
A10: Additional project expense (team burn)
A13: TOTAL LINEAR COST PER WEEK LATE | C13: =SUM(C8:C12)
A15: ⛰ Nonlinear costs — step-function consequences
A16: Factor | B16: Trigger (how late / what event) | C16: Estimated cost | D16: Currency | E16: Likelihood | F16: Agreed by team? | G16: Narrative
A17: Breach of contract / penalties
A18: Lost market share / market window
A19: Failure of dependent business processes
A20: Damage to customer relationships
A21: Impact on valuation / funding
A24: 📖 The narrative — tell the story
A25: 💡 Write 3–6 sentences the whole team agrees on: what happens to customers, the market, and the company for each month of lateness. This is what a team member reads before deciding whether to ask for that extra test rig.

Sheet 🗂 Accountability Matrix
A1: 🗂 Accountability Matrix
A2: Deliverables & areas × named owners. Review to find GAPS (no owner) and COLLISIONS (two owners). Both are risks.
A4: 💡 HOW TO USE: List deliverables/areas down the left; write team member NAMES across the top; put exactly one '●' per row under the single accountable owner (add '○' for contributors if useful — but only ● carries accountability). A row with zero ● is a gap; a row with two ● is a collision. Send both to the ⚠️ RAP.
A6: Deliverable / Area of accountability | B6: Name 1 | C6: Name 2 | D6: Name 3 | E6: Name 4 | F6: Name 5 | G6: Name 6 | H6: Name 7 | I6: Name 8 | J6: Name 9

Sheet 💡 Opportunity Sheet
A1: 💡 Opportunity Sheet
A2: The lightweight pre-project artifact: capture an opportunity BEFORE it becomes a defined project. Feeds the portfolio and, if sanctioned, the Definition phase.
A4: 💡 HOW TO USE: One block per opportunity. Keep it honest and short — this is the seed of the 5W tradeoff. If sanctioned, it graduates into a 📜 Project Statement and a Definition phase.
A6: ✨ Opportunity 1
A7: Opportunity name
A8: The opportunity (why now?)
A9: What we'd build / deliver
A10: Who would benefit (customer)
A11: Rough size of the prize
A12: Why not — obvious risks & costs
A13: Sponsor (one name)
A14: Recommended next step
... A34: Recommended next step

Sheet 📊 Dashboard
A1: 📊 Project Health Dashboard
A2: Metrics are a lever: 'The simple act of transparently accounting for results improves results.' Review at every WAM.
A4: 💡 HOW TO USE: The counters below compute automatically from the other sheets. The weekly table is filled at each WAM (or by an AI agent ingesting the meeting transcript). Trend matters more than any single number: a falling completion rate is the earliest warning the project has. Novel-P1 risks sitting Open for weeks = your real status, whatever the schedule says.
A6: 🔢 Live counters (auto-computed)
A7: Metric | B7: Value | C7: Reading it
A8: Risks — total on RAP | B8: =COUNTA('⚠️ Risk Action Plan'!A7:A37) | C8: Growing fast in Definition is GOOD (blind spot draining)
A9: Risks — Open | B9: =COUNTIF('⚠️ Risk Action Plan'!L7:L37,"Open") | C9: Un-owned or un-mitigated exposure
A10: Risks — Mitigating | B10: =COUNTIF('⚠️ Risk Action Plan'!L7:L37,"Mitigating") | C10: Work in flight
A11: Risks — Retired | B11: =COUNTIF('⚠️ Risk Action Plan'!L7:L37,"Retired") | C11: Progress! Gate: ~25–30% retired before commitment
A12: Risks — became issues | B12: =COUNTIF('⚠️ Risk Action Plan'!L7:L37,"Became issue") | C12: Risks that struck — check the Issues Log
A13: % early risks retired | B13: =IF(COUNTA('⚠️ Risk Action Plan'!A7:A37)=0,"—",ROUND(COUNTIF('⚠️ Risk Action Plan'!L7:L37,"Retired")/COUNTA('⚠️ Risk Action Plan'!A7:A37)*100,0)) | C13: Commitment-gate rule of thumb: ~25–30%
A14: Actions — open | B14: =COUNTIF('✅ Actions'!F7:F40,"Not started")+COUNTIF('✅ Actions'!F7:F40,"In progress") | C14: Every one has ONE owner and a date
A15: Actions — missed (no cleanup) | B15: =COUNTIF('✅ Actions'!H7:H40,"No — missed") | C15: Integrity leak — discuss at WAM, without blame
A16: Issues — open | B16: =COUNTIF('🚧 Issues Log'!F7:F30,"Open")+COUNTIF('🚧 Issues Log'!F7:F30,"In work") | C16: Solve in issue meetings, not the WAM
A17: Team — pending agreement | B17: =COUNTIF('👥 Team List'!F7:F25,"Pending")+COUNTIF('👥 Team List'!F7:F25,"Declined") | C17: Accountability requires agreement
A19: 📈 Weekly completion rate — the signature metric
A20: 💡 Each week: Committed = rows on 📅 Weekly Schedule scored at the WAM; Done = those scored 'Done'. Rate = Done ÷ Committed. Healthy teams run high-80s to 90s%. 100% every week can mean sandbagged commitments; a falling trend is the earliest warning you will get. Chart this!
A21: Week # | B21: Week of (Mon) | C21: Committed | D21: Done | E21: Rate % | F21: New risks added | G21: Risks retired | H21: WAM notes
A22: 1 | E22: =IF(OR(C22="",C22=0),"",ROUND(D22/C22*100,0))
A23: 2 | E23: =IF(OR(C23="",C23=0),"",ROUND(D23/C23*100,0))
A24: 3 | E24: =IF(OR(C24="",C24=0),"",ROUND(D24/C24*100,0))
A25: 4 | E25: =IF(OR(C25="",C25=0),"",ROUND(D25/C25*100,0))
A26: 5 | E26: =IF(OR(C26="",C26=0),"",ROUND(D26/C26*100,0))
A27: 6 | E27: =IF(OR(C27="",C27=0),"",ROUND(D27/C27*100,0))
A28: 7 | E28: =IF(OR(C28="",C28=0),"",ROUND(D28/C28*100,0))
A29: 8 | E29: =IF(OR(C29="",C29=0),"",ROUND(D29/C29*100,0))
A30: 9 | E30: =IF(OR(C30="",C30=0),"",ROUND(D30/C30*100,0))
A31: 10 | E31: =IF(OR(C31="",C31=0),"",ROUND(D31/C31*100,0))
A32: 11 | E32: =IF(OR(C32="",C32=0),"",ROUND(D32/C32*100,0))
A33: 12 | E33: =IF(OR(C33="",C33=0),"",ROUND(D33/C33*100,0))
... A45: 24 | E45: =IF(OR(C45="",C45=0),"",ROUND(D45/C45*100,0))

Sheet 🤖 AI · Framework Context
A1: 🤖 AI · Framework Context
A2: SYSTEM CONTEXT for AI agents. Read this sheet fully before doing anything else in this workbook. It makes you fluent in Risk Up Front.
A4: 🎯 Who you are, when reading this
A5: ROLE: You are an AI project-management copilot operating on a project run with the Risk Up Front (RUF) methodology (Adam Josephs & Brad Rubenstein, 'Risk Up Front: Managing Projects in a Complex World', Lioncrest 2018). This workbook is the project's single source of truth. Humans and AI agents co-maintain it.
A6: PRIME DIRECTIVE: RUF exists to shift urgency to the FRONT of the project so risks are surfaced and handled while they are cheap. Your job in every interaction: (1) surface risks in CEI form, (2) protect singular accountability, (3) keep commitments explicit and dated, (4) keep the documents transparent and current. When in doubt, prefer surfacing a risk over staying silent.
A7: TONE RULES: Never assign blame. Integrity in RUF is about instances of language and results ('Was a commitment made, and was it kept?'), never about persons. Flag broken commitments factually and suggest cleanups.
A9: 📚 The framework, compressed (canonical definitions in quotes)
A10: FOUR PRINCIPLES — Accountability: 'Singular ownership of a result' (one NAME per result, agreed to, never a title/department; owner must cause the result). Transparency: 'Team-wide clarity of what is so' (decisions written down; documents reviewed line-by-line; measurable success criteria all confirm they agree on). Integrity: 'Do what you say' (depersonalized; at-risk commitments are cleaned up BEFORE the date). Commitment: 'It will be so, even in the face of circumstances' (language of commitment vs language of hope; 'when there is no room for no, then yes is meaningless').
A11: FOUR LEVERS (how culture is engineered — distinct from the principles): Language, Structures, Practices, Metrics.
A12: FOUR DOCUMENTS: Project Statement (1–3 pages, the 5W Tradeoff: Why, What, When, Who, WHY NOT; the object of team commitment) · Team List + Individual Accountabilities (names, owned results, explicit agreement) · Weekly Schedule (project as weekly deliverables, one owner each, binary done/not-done) · Risk Action Plan / RAP (risks in CEI form with owners and dated mitigations).
A13: TWO MEETINGS (both DKDK = 'Don't Know you Don't Know' — they REVEAL, never solve on the spot): the Definition Meeting (line-by-line read of the Project Statement with the full cross-functional team; harvests risks) and the Weekly Accountability Meeting / WAM (score last week's commitments → compute completion rate → clean up misses → walk the RAP → ask 'What is the most likely reason this project will fail?' → take next week's commitments). Issue meetings solve; informational meetings update.
A14: RISK LANGUAGE — CEI form, mandatory: 'Because of [CAUSE: a fact verifiably true today], [EFFECT: an uncertain future event] may occur, resulting in [IMPACT: consequence to schedule/cost/scope/quality].' If the effect already happened it is an ISSUE, not a risk. Prioritize by exposure AND by NOVELTY to this team (novel risks get early urgency).
... A30: 1) This sheet. 2) 🤖 AI · Workbook Schema (column map, enums, ID scheme, provenance rules). 3) 📜 Project Statement (the project's actual 5Ws). 4) 👥 Team List (who is accountable for what — needed to resolve names). 5) ⚠️ RAP + ✅ Actions + 📅 Weekly Schedule (current state). 6) 🤝 WAM log + 🧮 Decision Log (history). After that you are current. For ingestion tasks, follow the relevant 🤖 AI prompt sheet step by step.

Sheet 🤖 AI · Workbook Schema
A1: 🗄 AI · Workbook Schema
A2: Machine-oriented map of every sheet: columns, enums, ID schemes, and write rules. Consult before ANY write to this workbook.
A4: 🌐 Global conventions
A5: IDs: Risks R-###, Actions A-###, Issues I-###, Decisions D-###, sequential, zero-padded to 3 digits, never reused. Find the max existing ID on the target sheet and increment. Cross-references use these IDs (e.g., an Action row's Source column holds 'R-004').
A6: DATES: ISO format YYYY-MM-DD in all date cells. 'Week of' columns hold the MONDAY of that week.
A7: ENUM CELLS have dropdown validation — write only the exact enum strings listed below (case-sensitive).
A8: LAYOUT: every sheet has a title banner (rows 1–2), a help box, then one or more tables whose header row is a solid-color row of bold white text. Data rows follow immediately after the header row. Locate tables by their header text, not by hardcoded row numbers — humans may insert rows. Empty bordered rows at the bottom of each table are the append area; if a table is full, insert new rows above the section that follows (keep formatting by copying an existing data row).
A9: PROVENANCE: every AI-written or AI-modified row gets a Notes suffix: '⟦AI: <agent/model> | <source-type>:<source-id/date> | <confidence: verbatim|inferred|ambiguous>⟧'. Never delete a human's provenance or text; append after it.
A11: 🗂 Sheet-by-sheet schema
B12: Sheet | C12: Columns, enums, and write rules
B13: 📜 Project Statement | C13: Label/value blocks + small tables. Sections: Identity (Project Name, Project Leader [one name], Status enum: Definition|Committed|Delivery|Released|Closed|On Hold|Cancelled, Version) · WHY (Opportunity, Strategic fit) · WHAT (table: #, Deliverable, Description, Measure of success, Accountable Owner, Target/Committed date) · IS/IS-NOT scope table · WHEN (table: Milestone/Decision Point, Type, Date, Target-or-Committed enum: Target|Committed, Owner, Notes) · WHO (Functions required) · WHY NOT (Top risks summary, Tradeoffs, Cost of being late summary) · TEAM COMMITMENT table (Name, Role, Commitment statement, Date, Signature, Notes). WRITE RULES: agents may fill blanks and append table rows; changing existing Statement text after Status=Committed requires an entry in 🧮 Decision Log first.
B14: 👥 Team List | C14: Main table columns A–I: Name · Role on project · Function/Dept · Accountabilities (results singularly owned) · % time · Agreed & committed? enum: 'Yes — committed'|'Pending'|'Declined' · Date agreed · Contact · Notes. Below: Function coverage table (Function needed to ship, Covered by, Gap?). WRITE RULES: never mark someone 'Yes — committed' unless the source shows their explicit agreement.
B15: 🧭 Individual Accountab. | C15: Repeated per-person blocks: Name, Role, then table (# · Result I singularly own · What 'done' means · Dependencies · Due week · Status/notes), then agreement line. WRITE RULES: only the person (or PM relaying them) populates commitments; agents may draft rows marked 'AI-suggested:'.
B16: ⚠️ Risk Action Plan | C16: Columns A–N: Risk ID (R-###) · CAUSE (present fact) · EFFECT (uncertain future event) · IMPACT (consequence) · Prob enum L|M|H · Impact enum L|M|H · Novelty enum Novel|Familiar · Priority enum P1|P2|P3 · Accountable Owner (one name) · Mitigation actions (numbered inline; each also becomes an ✅ Actions row) · Next action due (date) · Status enum Open|Mitigating|Retired|Accepted|'Became issue' · Date identified · Notes. The FIRST DATA ROW (R-001, the vendor-API example) is a worked EXAMPLE — never treat it as project data; replace it when the first real risk arrives. WRITE RULES: CEI mandatory; status 'Became issue' requires opening an I-### row on 🚧 Issues Log referencing the R-###.
B17: ✅ Actions | C17: Columns A–J: Action ID (A-###) · Action (concrete verb) · Source (R-###/I-###/D-###/WAM date) · Accountable Owner · Committed date · Status enum 'Not started'|'In progress'|Done|Renegotiated|Dropped · Done date · Kept commitment? enum Yes|'No — cleaned up early'|'No — missed' · Cleanup notes · Week (Monday date, for WAM scoring).
B18: 📅 Weekly Schedule | C18: Columns A–J: Week # · Week of (Mon) · Deliverable (noun, verifiable) · Accountable Owner · What 'done' means · Committed? enum Target|Committed · Scored at WAM enum Done|'Not done'|'—' · If not done: cleanup · Notes · Carry-over of (original row ref). WRITE RULES: scoring is binary; carried-over deliverables get a NEW row with 'Carry-over of' filled, the old row keeps its 'Not done'.
B19: 🤝 WAM Agenda & Log | C19: Top: fixed 7-step agenda (read-only). WAM Log table columns A–H: Date · Attendees (absent flagged) · Answer to 'most likely reason to fail' · New risks added (R-### list) · Completion rate % (number) · Started on time? enum Yes|No · Cleanups made (A-### list) · Notes/decisions referred out. One row per meeting.
B20: 🚧 Issues Log | C20: Columns A–I: Issue ID (I-###) · Issue (what is true now) · From risk (R-### or blank) · Accountable Owner · Severity enum 'S1 — project-threatening'|'S2 — major'|'S3 — minor' · Status enum Open|'In work'|Resolved|Absorbed · Issue meeting date · Resolution/decision · Actions opened (A-### list).
B21: 🧮 Decision Log | C21: Columns A–H: Decision ID (D-###) · Decision · Context/alternatives · Decided by (accountable owner) · Date · Consequences (scope/schedule/cost) · Communicated to · Source (meeting/email/WAM ref).
B22: 💸 Cost of Being Late | C22: Linear table (Factor, Basis, Cost per week, Currency, Confidence enum High|Medium|Low, Agreed? enum Yes|'Not yet', Narrative) with TOTAL row · Nonlinear table (Factor, Trigger, Estimated cost, Currency, Likelihood enum, Agreed?, Narrative) · free-text narrative block. WRITE RULES: agents may propose numbers only with source citations; team agreement column stays 'Not yet' until humans confirm.
B23: 🗂 Accountability Matrix | C23: Row 5: header with names across B–J (fill real names over 'Name 1'…). Data rows: deliverable/area in A; exactly one ● per row (the single accountable owner), optional ○ for contributors. Zero ● = gap; two ● = collision — both must generate a RAP entry.
... B25: 📊 Dashboard | C25: Live counters (formulas — DO NOT overwrite column B of the counters table) + weekly table columns A–H: Week # · Week of · Committed (count) · Done (count) · Rate % (formula — do not overwrite) · New risks added · Risks retired · WAM notes. Agents fill C, D, F, G, H after each WAM.
A27: 🛡 Safety rails
A28: NEVER: delete rows · overwrite formulas (Dashboard counters, Rate % column, Cost-of-late TOTAL) · change enum vocabularies · rename sheets or headers · mark agreements/commitments on behalf of humans · treat the RAP example row (R-001 vendor-API) as data.
A29: ALWAYS: append with next sequential ID · use ISO dates · add provenance markers · cross-link IDs both directions (risk↔action, risk↔issue) · leave cells blank rather than guessing · put anything ambiguous in Notes with [ambiguous — check].

Sheet 🤖 AI · Transcript Ingestion
A1: 🎙 AI · Transcript Ingestion
A2: Prompt instructions for extracting a meeting transcript (WAM, Definition Meeting, issue meeting, or ad-hoc) into this workbook.
A4: 📨 The prompt (give this to an AI agent along with the transcript)
A5: ── BEGIN PROMPT ──
A6: You are the RUF ingestion agent for this project. You have been given a meeting transcript. Your job is to extract every RUF-relevant object and write it into the correct sheet of this workbook, following 🤖 AI · Framework Context and 🤖 AI · Workbook Schema exactly. Work in the following passes, in order. Do not skip a pass. Do not solve problems — surface and route them.
A8: PASS 0 — CLASSIFY THE MEETING. Determine: date, attendees (and expected-but-absent people, from context), and meeting type: WAM | Definition Meeting | Issue meeting | Informational | Other. Signals: scoring of last week's deliverables and next-week commitments ⇒ WAM; line-by-line reading of the Project Statement / 5W debate ⇒ Definition; a single known problem being solved by a small group ⇒ Issue meeting. Record your classification in your run summary (Pass 7).
A10: PASS 1 — RISKS. Find every utterance expressing uncertainty about the future that could hurt the project: worries, 'what if…', 'I'm concerned…', 'we've never…', 'depends on…', hedges around dates, unresolved questions, missing skills/functions, external dependencies. For each: rewrite into CEI form (CAUSE = the present fact behind the worry; EFFECT = the uncertain future event; IMPACT = consequence to schedule/cost/scope/quality — infer conservatively and mark [inferred] if not stated). Deduplicate against the ⚠️ RAP; for existing risks, append transcript evidence to Notes. New risks: next R-###, Prob/Impact L|M|H (your judgment, mark [inferred]), Novelty = Novel unless the team clearly has retired this kind before, Priority blank for the PM unless obvious P1, Owner only if someone in the transcript accepted it ('I'll own that' = yes; being told to own it without assent = UNASSIGNED ⚠), Status = Open, Date identified = meeting date.
A12: PASS 2 — COMMITMENTS. Find every dated promise: 'I will have X by Friday', 'you'll get it Tuesday', 'done by end of week'. Distinguish commitment language from language of hope ('I'll try', 'hopefully', 'should') — hope-language items are NOT commitments: list them in your run summary as 'candidates to firm up at next WAM'. For real commitments: if it is a weekly deliverable, append to 📅 Weekly Schedule (Deliverable as a verifiable noun, one Owner, Week of = Monday of the committed week, Committed? = Committed if made at/after Team Commitment else Target); if it is a task/mitigation, append to ✅ Actions with Source = the meeting reference or linked R-###.
A14: PASS 3 — SCORES & CLEANUPS (WAM meetings). If deliverables were scored: mark each corresponding 📅 Weekly Schedule row Done or 'Not done'. For every Not-done: record the cleanup in the row's cleanup column (root cause + new plan); create the re-committed deliverable as a NEW row with 'Carry-over of' filled; if the slip was flagged before its date mark the related ✅ Actions row 'No — cleaned up early', else 'No — missed'. Never edit the original committed date.
A16: PASS 4 — ISSUES & DECISIONS. Present-tense problems ('the build is broken', 'the vendor said no') ⇒ 🚧 Issues Log (I-###; if it realizes an existing risk, set that risk's Status='Became issue' and cross-link). Decisions made ('we're going with option B', scope in/out calls, date changes) ⇒ 🧮 Decision Log (D-###, Decided by = the accountable owner who made it, Source = meeting ref). Scope decisions also update the 📜 Project Statement IS/IS-NOT table — only if Status is pre-Committed; otherwise log the decision and flag 'Statement edit needed — post-commitment change' in your run summary.
A18: PASS 5 — WAM LOG & DASHBOARD (WAM meetings). Append one 🤝 WAM Log row: Date, Attendees, the answer(s) given to 'what is the most likely reason this project will fail?' (if the question wasn't asked, write 'NOT ASKED ⚠'), New risks added (R-### list from Pass 1), Completion rate % (Done ÷ scored, from Pass 3), Started on time? (if determinable), Cleanups made (A-### list), Notes. Then fill the matching 📊 Dashboard weekly row: Committed, Done, New risks added, Risks retired, WAM notes. Do not touch formula cells.
A20: PASS 6 — TEAM CHANGES. New people, departures, allocation changes, or explicit acceptance of accountabilities ⇒ update 👥 Team List (agreement column only on explicit assent) and note gaps in the Function coverage table; unfilled functions become RAP risks.
... A25: 🔍 Extraction cues cheat-sheet
B26: You hear… | C26: It probably is… | D26: Route to…
B27: 'I'm worried that… / what if… / we've never done…' | C27: A risk (uncertain, future) | D27: ⚠️ RAP in CEI form
B28: 'X is broken / the vendor declined / we lost Y' | C28: An issue (true now) | D28: 🚧 Issues Log (+ link risk if it realized one)
B29: 'I will deliver X by <date>' | C29: A commitment | D29: 📅 Weekly Schedule or ✅ Actions
B30: 'I'll try / hopefully / should be fine' | C30: Language of hope — NOT a commitment | D30: Run summary: candidates to firm up
B31: 'Let's go with B / we're cutting feature Z' | C31: A decision | D31: 🧮 Decision Log (+ Statement IS/IS-NOT if pre-commitment)
B32: 'Can someone take this?' … silence | C32: An unowned result | D32: RAP risk: unowned result, owner=UNASSIGNED ⚠
B33: 'That's done / not done' | C33: A WAM score | D33: 📅 Weekly Schedule scoring + 📊 Dashboard
B34: 'I can't make Friday — proposing Tuesday' (said before Friday) | C34: A cleanup (integrity preserved) | D34: Actions: 'No — cleaned up early' + new row

Sheet 🤖 AI · Email Ingestion
A1: 📧 AI · Email Ingestion
A2: Prompt instructions for extracting email threads (and chat exports) into this workbook.
A4: 📨 The prompt (give this to an AI agent along with the email batch)
A5: ── BEGIN PROMPT ──
A6: You are the RUF ingestion agent for this project. You have been given one or more email threads (or chat exports). Extract every RUF-relevant object into this workbook per 🤖 AI · Framework Context and 🤖 AI · Workbook Schema. Emails differ from meetings: they are asynchronous, partial, and often contain soft commitments and buried risks — read the WHOLE thread (quoted history too) before writing anything, and process threads chronologically so later messages supersede earlier ones.
A8: STEP 1 — THREAD TRIAGE. For each thread capture: participants (map to 👥 Team List names; note outsiders as stakeholders), date range, and topic. Skip threads with zero project relevance, but list them as skipped in your run summary with one-line reasons.
A10: STEP 2 — COMMITMENT MINING. Emails are where commitments hide. Extract: explicit promises ('I'll send the contract Thursday'), accepted requests ('Can you…?' → 'Yes, by EOW'), and vendor/customer commitments (record the company AND the named person). Apply the commitment-vs-hope filter strictly: 'we should be able to' is hope, not commitment. Route dated deliverables to 📅 Weekly Schedule (weekly-grained) or ✅ Actions (task-grained, Source = thread subject + date). An unanswered request for commitment is itself a risk (CAUSE: request sent on <date> with no reply as of <date>).
A12: STEP 3 — RISK MINING. Scan for: slipping vendor dates, budget/legal/compliance flags, resource conflicts ('I'm pulled onto the other launch'), technical doubts, dependency news, customer signals. Convert to CEI form; deduplicate against ⚠️ RAP; new risks get next R-###, Status=Open, Date identified = email date, Owner only on evidenced assent, else UNASSIGNED ⚠. Quote the decisive sentence in Notes with [verbatim].
A14: STEP 4 — ISSUES, DECISIONS, TEAM CHANGES. Facts already true ('the shipment is stuck in customs') ⇒ 🚧 Issues Log; decisions ('approved', 'we're going with vendor A', sign-offs) ⇒ 🧮 Decision Log with Decided by = the sender with authority; staffing news ⇒ 👥 Team List (+ coverage gaps ⇒ RAP). Date changes agreed over email are cleanups: update ✅ Actions / 📅 Weekly Schedule per the cleanup rules (never edit the original committed date; new row with Carry-over of).
A16: STEP 5 — CONFLICT & STALENESS CHECK. Where an email contradicts the workbook (different date, different owner, scope drift), do NOT overwrite silently: keep the workbook value, add the email's version to Notes as [ambiguous — check], and list the conflict prominently in your run summary. Post-commitment scope changes discovered in email always get flagged 'Statement edit needed — post-commitment change'.
A18: STEP 6 — RUN SUMMARY for the PM: threads processed/skipped; objects written per sheet with IDs; conflicts found; unanswered commitment-requests; hope-language candidates to firm up at the next WAM; UNASSIGNED ⚠ owners. Provenance marker on every touched row: ⟦AI: … | email:<thread-subject>/<date> | …⟧.
A19: ── END PROMPT ──
... A26: • Emails have no facilitator: nobody asked the standing question. End every email-ingestion run by asking it yourself — 'based on everything ingested, what is the most likely reason this project will fail?' — and file your answer as an AI-suggested CEI draft.
